<?xml version="1.0" ?>
<!-- =================================================================================== -->
<!-- |    This document was autogenerated by xacro from planar_snake.xacro             | -->
<!-- |    EDITING THIS FILE BY HAND IS NOT RECOMMENDED                                 | -->
<!-- =================================================================================== -->
<robot name="snake" xmlns:xacro="http://www.ros.org/wiki/xacro">
  <gazebo>
    <plugin filename="libgazebo_ros_control.so" name="gazebo_ros_control">
      <robotNamespace>/planar_snake</robotNamespace>
    </plugin>
  </gazebo>
  <!-- Used for fixing robot to Gazebo 'base_link' -->
  <link name="base_link"/>
  <joint name="fixed" type="fixed">
    <parent link="base_link"/>
    <child link="car_1"/>
  </joint>
  <link name="car_1">
    <collision>
      <origin rpy="0 0 0" xyz="-0.175 0 0.08"/>
      <geometry>
        <box size="0.25 0.1 0.1"/>
      </geometry>
    </collision>
    <visual>
      <origin rpy="0 0 0" xyz="-0.175 0 0.08"/>
      <geometry>
        <box size="0.25 0.1 0.1"/>
      </geometry>
    </visual>
    <inertial>
      <origin rpy="0 0 0" xyz="-0.175 0 0.08"/>
      <mass value="1"/>
      <inertia ixx="1.0" ixy="0.0" ixz="0.0" iyy="1.0" iyz="0.0" izz="1.0"/>
    </inertial>
  </link>
  <link name="wheel_left_1">
    <collision>
      <origin rpy="0 1.57079632679 1.57079632679" xyz="0 0 0"/>
      <geometry>
        <cylinder length="0.02" radius="0.05"/>
      </geometry>
    </collision>
    <visual>
      <origin rpy="0 1.57079632679 1.57079632679" xyz="0 0 0"/>
      <geometry>
        <cylinder length="0.02" radius="0.05"/>
      </geometry>
    </visual>
    <inertial>
      <origin rpy="0 1.57079632679 1.57079632679" xyz="0 0 0"/>
      <mass value="1"/>
      <inertia ixx="1.0" ixy="0.0" ixz="0.0" iyy="1.0" iyz="0.0" izz="1.0"/>
    </inertial>
  </link>
  <gazebo reference="wheel_left_1">
    <mu1>1.5</mu1>
    <mu2>1.5</mu2>
  </gazebo>
  <link name="wheel_right_1">
    <collision>
      <origin rpy="0 1.57079632679 1.57079632679" xyz="0 0 0"/>
      <geometry>
        <cylinder length="0.02" radius="0.05"/>
      </geometry>
    </collision>
    <visual>
      <origin rpy="0 1.57079632679 1.57079632679" xyz="0 0 0"/>
      <geometry>
        <cylinder length="0.02" radius="0.05"/>
      </geometry>
    </visual>
    <inertial>
      <origin rpy="0 1.57079632679 1.57079632679" xyz="0 0 0"/>
      <mass value="1"/>
      <inertia ixx="1.0" ixy="0.0" ixz="0.0" iyy="1.0" iyz="0.0" izz="1.0"/>
    </inertial>
  </link>
  <gazebo reference="wheel_right_1">
    <mu1>1.5</mu1>
    <mu2>1.5</mu2>
  </gazebo>
  <link name="caster_front_1">
    <visual>
      <origin rpy="0 0 0" xyz="0 0 0"/>
      <geometry>
        <sphere radius="0.05"/>
      </geometry>
    </visual>
    <inertial>
      <origin rpy="0 0 0" xyz="0 0 0"/>
      <mass value="1"/>
      <inertia ixx="1.0" ixy="0.0" ixz="0.0" iyy="1.0" iyz="0.0" izz="1.0"/>
    </inertial>
  </link>
  <link name="caster_back_1">
    <visual>
      <origin rpy="0 0 0" xyz="0 0 0"/>
      <geometry>
        <sphere radius="0.05"/>
      </geometry>
    </visual>
    <inertial>
      <origin rpy="0 0 0" xyz="0 0 0"/>
      <mass value="1"/>
      <inertia ixx="1.0" ixy="0.0" ixz="0.0" iyy="1.0" iyz="0.0" izz="1.0"/>
    </inertial>
  </link>
  <joint name="leftJoint_1" type="continuous">
    <parent link="car_1"/>
    <child link="wheel_left_1"/>
    <origin rpy="0 0 0" xyz="-0.175 0.062 0.05"/>
    <axis xyz="0 1 0"/>
  </joint>
  <joint name="rightJoint_1" type="continuous">
    <parent link="car_1"/>
    <child link="wheel_right_1"/>
    <origin rpy="0 0 0" xyz="-0.175 -0.062 0.05"/>
    <axis xyz="0 1 0"/>
  </joint>
  <joint name="frontJoint_1" type="fixed">
    <parent link="car_1"/>
    <child link="caster_front_1"/>
    <origin rpy="0 0 0" xyz="-0.05 0 0.08"/>
  </joint>
  <joint name="backJoint_1" type="fixed">
    <parent link="car_1"/>
    <child link="caster_back_1"/>
    <origin rpy="0 0 0" xyz="-0.3 0 0.08"/>
  </joint>
  <link name="car_2">
    <collision>
      <origin rpy="0 0 0" xyz="-0.175 0 0.08"/>
      <geometry>
        <box size="0.25 0.1 0.1"/>
      </geometry>
    </collision>
    <visual>
      <origin rpy="0 0 0" xyz="-0.175 0 0.08"/>
      <geometry>
        <box size="0.25 0.1 0.1"/>
      </geometry>
    </visual>
    <inertial>
      <origin rpy="0 0 0" xyz="-0.175 0 0.08"/>
      <mass value="1"/>
      <inertia ixx="1.0" ixy="0.0" ixz="0.0" iyy="1.0" iyz="0.0" izz="1.0"/>
    </inertial>
  </link>
  <link name="wheel_left_2">
    <collision>
      <origin rpy="0 1.57079632679 1.57079632679" xyz="0 0 0"/>
      <geometry>
        <cylinder length="0.02" radius="0.05"/>
      </geometry>
    </collision>
    <visual>
      <origin rpy="0 1.57079632679 1.57079632679" xyz="0 0 0"/>
      <geometry>
        <cylinder length="0.02" radius="0.05"/>
      </geometry>
    </visual>
    <inertial>
      <origin rpy="0 1.57079632679 1.57079632679" xyz="0 0 0"/>
      <mass value="1"/>
      <inertia ixx="1.0" ixy="0.0" ixz="0.0" iyy="1.0" iyz="0.0" izz="1.0"/>
    </inertial>
  </link>
  <gazebo reference="wheel_left_2">
    <mu1>1.5</mu1>
    <mu2>1.5</mu2>
  </gazebo>
  <link name="wheel_right_2">
    <collision>
      <origin rpy="0 1.57079632679 1.57079632679" xyz="0 0 0"/>
      <geometry>
        <cylinder length="0.02" radius="0.05"/>
      </geometry>
    </collision>
    <visual>
      <origin rpy="0 1.57079632679 1.57079632679" xyz="0 0 0"/>
      <geometry>
        <cylinder length="0.02" radius="0.05"/>
      </geometry>
    </visual>
    <inertial>
      <origin rpy="0 1.57079632679 1.57079632679" xyz="0 0 0"/>
      <mass value="1"/>
      <inertia ixx="1.0" ixy="0.0" ixz="0.0" iyy="1.0" iyz="0.0" izz="1.0"/>
    </inertial>
  </link>
  <gazebo reference="wheel_right_2">
    <mu1>1.5</mu1>
    <mu2>1.5</mu2>
  </gazebo>
  <link name="caster_front_2">
    <visual>
      <origin rpy="0 0 0" xyz="0 0 0"/>
      <geometry>
        <sphere radius="0.05"/>
      </geometry>
    </visual>
    <inertial>
      <origin rpy="0 0 0" xyz="0 0 0"/>
      <mass value="1"/>
      <inertia ixx="1.0" ixy="0.0" ixz="0.0" iyy="1.0" iyz="0.0" izz="1.0"/>
    </inertial>
  </link>
  <link name="caster_back_2">
    <visual>
      <origin rpy="0 0 0" xyz="0 0 0"/>
      <geometry>
        <sphere radius="0.05"/>
      </geometry>
    </visual>
    <inertial>
      <origin rpy="0 0 0" xyz="0 0 0"/>
      <mass value="1"/>
      <inertia ixx="1.0" ixy="0.0" ixz="0.0" iyy="1.0" iyz="0.0" izz="1.0"/>
    </inertial>
  </link>
  <joint name="leftJoint_2" type="continuous">
    <parent link="car_2"/>
    <child link="wheel_left_2"/>
    <origin rpy="0 0 0" xyz="-0.175 0.062 0.05"/>
    <axis xyz="0 1 0"/>
  </joint>
  <joint name="rightJoint_2" type="continuous">
    <parent link="car_2"/>
    <child link="wheel_right_2"/>
    <origin rpy="0 0 0" xyz="-0.175 -0.062 0.05"/>
    <axis xyz="0 1 0"/>
  </joint>
  <joint name="frontJoint_2" type="fixed">
    <parent link="car_2"/>
    <child link="caster_front_2"/>
    <origin rpy="0 0 0" xyz="-0.05 0 0.08"/>
  </joint>
  <joint name="backJoint_2" type="fixed">
    <parent link="car_2"/>
    <child link="caster_back_2"/>
    <origin rpy="0 0 0" xyz="-0.3 0 0.08"/>
  </joint>
  <link name="car_3">
    <collision>
      <origin rpy="0 0 0" xyz="-0.175 0 0.08"/>
      <geometry>
        <box size="0.25 0.1 0.1"/>
      </geometry>
    </collision>
    <visual>
      <origin rpy="0 0 0" xyz="-0.175 0 0.08"/>
      <geometry>
        <box size="0.25 0.1 0.1"/>
      </geometry>
    </visual>
    <inertial>
      <origin rpy="0 0 0" xyz="-0.175 0 0.08"/>
      <mass value="1"/>
      <inertia ixx="1.0" ixy="0.0" ixz="0.0" iyy="1.0" iyz="0.0" izz="1.0"/>
    </inertial>
  </link>
  <link name="wheel_left_3">
    <collision>
      <origin rpy="0 1.57079632679 1.57079632679" xyz="0 0 0"/>
      <geometry>
        <cylinder length="0.02" radius="0.05"/>
      </geometry>
    </collision>
    <visual>
      <origin rpy="0 1.57079632679 1.57079632679" xyz="0 0 0"/>
      <geometry>
        <cylinder length="0.02" radius="0.05"/>
      </geometry>
    </visual>
    <inertial>
      <origin rpy="0 1.57079632679 1.57079632679" xyz="0 0 0"/>
      <mass value="1"/>
      <inertia ixx="1.0" ixy="0.0" ixz="0.0" iyy="1.0" iyz="0.0" izz="1.0"/>
    </inertial>
  </link>
  <gazebo reference="wheel_left_3">
    <mu1>1.5</mu1>
    <mu2>1.5</mu2>
  </gazebo>
  <link name="wheel_right_3">
    <collision>
      <origin rpy="0 1.57079632679 1.57079632679" xyz="0 0 0"/>
      <geometry>
        <cylinder length="0.02" radius="0.05"/>
      </geometry>
    </collision>
    <visual>
      <origin rpy="0 1.57079632679 1.57079632679" xyz="0 0 0"/>
      <geometry>
        <cylinder length="0.02" radius="0.05"/>
      </geometry>
    </visual>
    <inertial>
      <origin rpy="0 1.57079632679 1.57079632679" xyz="0 0 0"/>
      <mass value="1"/>
      <inertia ixx="1.0" ixy="0.0" ixz="0.0" iyy="1.0" iyz="0.0" izz="1.0"/>
    </inertial>
  </link>
  <gazebo reference="wheel_right_3">
    <mu1>1.5</mu1>
    <mu2>1.5</mu2>
  </gazebo>
  <link name="caster_front_3">
    <visual>
      <origin rpy="0 0 0" xyz="0 0 0"/>
      <geometry>
        <sphere radius="0.05"/>
      </geometry>
    </visual>
    <inertial>
      <origin rpy="0 0 0" xyz="0 0 0"/>
      <mass value="1"/>
      <inertia ixx="1.0" ixy="0.0" ixz="0.0" iyy="1.0" iyz="0.0" izz="1.0"/>
    </inertial>
  </link>
  <link name="caster_back_3">
    <visual>
      <origin rpy="0 0 0" xyz="0 0 0"/>
      <geometry>
        <sphere radius="0.05"/>
      </geometry>
    </visual>
    <inertial>
      <origin rpy="0 0 0" xyz="0 0 0"/>
      <mass value="1"/>
      <inertia ixx="1.0" ixy="0.0" ixz="0.0" iyy="1.0" iyz="0.0" izz="1.0"/>
    </inertial>
  </link>
  <joint name="leftJoint_3" type="continuous">
    <parent link="car_3"/>
    <child link="wheel_left_3"/>
    <origin rpy="0 0 0" xyz="-0.175 0.062 0.05"/>
    <axis xyz="0 1 0"/>
  </joint>
  <joint name="rightJoint_3" type="continuous">
    <parent link="car_3"/>
    <child link="wheel_right_3"/>
    <origin rpy="0 0 0" xyz="-0.175 -0.062 0.05"/>
    <axis xyz="0 1 0"/>
  </joint>
  <joint name="frontJoint_3" type="fixed">
    <parent link="car_3"/>
    <child link="caster_front_3"/>
    <origin rpy="0 0 0" xyz="-0.05 0 0.08"/>
  </joint>
  <joint name="backJoint_3" type="fixed">
    <parent link="car_3"/>
    <child link="caster_back_3"/>
    <origin rpy="0 0 0" xyz="-0.3 0 0.08"/>
  </joint>
  <link name="car_4">
    <collision>
      <origin rpy="0 0 0" xyz="-0.175 0 0.08"/>
      <geometry>
        <box size="0.25 0.1 0.1"/>
      </geometry>
    </collision>
    <visual>
      <origin rpy="0 0 0" xyz="-0.175 0 0.08"/>
      <geometry>
        <box size="0.25 0.1 0.1"/>
      </geometry>
    </visual>
    <inertial>
      <origin rpy="0 0 0" xyz="-0.175 0 0.08"/>
      <mass value="1"/>
      <inertia ixx="1.0" ixy="0.0" ixz="0.0" iyy="1.0" iyz="0.0" izz="1.0"/>
    </inertial>
  </link>
  <link name="wheel_left_4">
    <collision>
      <origin rpy="0 1.57079632679 1.57079632679" xyz="0 0 0"/>
      <geometry>
        <cylinder length="0.02" radius="0.05"/>
      </geometry>
    </collision>
    <visual>
      <origin rpy="0 1.57079632679 1.57079632679" xyz="0 0 0"/>
      <geometry>
        <cylinder length="0.02" radius="0.05"/>
      </geometry>
    </visual>
    <inertial>
      <origin rpy="0 1.57079632679 1.57079632679" xyz="0 0 0"/>
      <mass value="1"/>
      <inertia ixx="1.0" ixy="0.0" ixz="0.0" iyy="1.0" iyz="0.0" izz="1.0"/>
    </inertial>
  </link>
  <gazebo reference="wheel_left_4">
    <mu1>1.5</mu1>
    <mu2>1.5</mu2>
  </gazebo>
  <link name="wheel_right_4">
    <collision>
      <origin rpy="0 1.57079632679 1.57079632679" xyz="0 0 0"/>
      <geometry>
        <cylinder length="0.02" radius="0.05"/>
      </geometry>
    </collision>
    <visual>
      <origin rpy="0 1.57079632679 1.57079632679" xyz="0 0 0"/>
      <geometry>
        <cylinder length="0.02" radius="0.05"/>
      </geometry>
    </visual>
    <inertial>
      <origin rpy="0 1.57079632679 1.57079632679" xyz="0 0 0"/>
      <mass value="1"/>
      <inertia ixx="1.0" ixy="0.0" ixz="0.0" iyy="1.0" iyz="0.0" izz="1.0"/>
    </inertial>
  </link>
  <gazebo reference="wheel_right_4">
    <mu1>1.5</mu1>
    <mu2>1.5</mu2>
  </gazebo>
  <link name="caster_front_4">
    <visual>
      <origin rpy="0 0 0" xyz="0 0 0"/>
      <geometry>
        <sphere radius="0.05"/>
      </geometry>
    </visual>
    <inertial>
      <origin rpy="0 0 0" xyz="0 0 0"/>
      <mass value="1"/>
      <inertia ixx="1.0" ixy="0.0" ixz="0.0" iyy="1.0" iyz="0.0" izz="1.0"/>
    </inertial>
  </link>
  <link name="caster_back_4">
    <visual>
      <origin rpy="0 0 0" xyz="0 0 0"/>
      <geometry>
        <sphere radius="0.05"/>
      </geometry>
    </visual>
    <inertial>
      <origin rpy="0 0 0" xyz="0 0 0"/>
      <mass value="1"/>
      <inertia ixx="1.0" ixy="0.0" ixz="0.0" iyy="1.0" iyz="0.0" izz="1.0"/>
    </inertial>
  </link>
  <joint name="leftJoint_4" type="continuous">
    <parent link="car_4"/>
    <child link="wheel_left_4"/>
    <origin rpy="0 0 0" xyz="-0.175 0.062 0.05"/>
    <axis xyz="0 1 0"/>
  </joint>
  <joint name="rightJoint_4" type="continuous">
    <parent link="car_4"/>
    <child link="wheel_right_4"/>
    <origin rpy="0 0 0" xyz="-0.175 -0.062 0.05"/>
    <axis xyz="0 1 0"/>
  </joint>
  <joint name="frontJoint_4" type="fixed">
    <parent link="car_4"/>
    <child link="caster_front_4"/>
    <origin rpy="0 0 0" xyz="-0.05 0 0.08"/>
  </joint>
  <joint name="backJoint_4" type="fixed">
    <parent link="car_4"/>
    <child link="caster_back_4"/>
    <origin rpy="0 0 0" xyz="-0.3 0 0.08"/>
  </joint>
  <link name="car_5">
    <collision>
      <origin rpy="0 0 0" xyz="-0.175 0 0.08"/>
      <geometry>
        <box size="0.25 0.1 0.1"/>
      </geometry>
    </collision>
    <visual>
      <origin rpy="0 0 0" xyz="-0.175 0 0.08"/>
      <geometry>
        <box size="0.25 0.1 0.1"/>
      </geometry>
    </visual>
    <inertial>
      <origin rpy="0 0 0" xyz="-0.175 0 0.08"/>
      <mass value="1"/>
      <inertia ixx="1.0" ixy="0.0" ixz="0.0" iyy="1.0" iyz="0.0" izz="1.0"/>
    </inertial>
  </link>
  <link name="wheel_left_5">
    <collision>
      <origin rpy="0 1.57079632679 1.57079632679" xyz="0 0 0"/>
      <geometry>
        <cylinder length="0.02" radius="0.05"/>
      </geometry>
    </collision>
    <visual>
      <origin rpy="0 1.57079632679 1.57079632679" xyz="0 0 0"/>
      <geometry>
        <cylinder length="0.02" radius="0.05"/>
      </geometry>
    </visual>
    <inertial>
      <origin rpy="0 1.57079632679 1.57079632679" xyz="0 0 0"/>
      <mass value="1"/>
      <inertia ixx="1.0" ixy="0.0" ixz="0.0" iyy="1.0" iyz="0.0" izz="1.0"/>
    </inertial>
  </link>
  <gazebo reference="wheel_left_5">
    <mu1>1.5</mu1>
    <mu2>1.5</mu2>
  </gazebo>
  <link name="wheel_right_5">
    <collision>
      <origin rpy="0 1.57079632679 1.57079632679" xyz="0 0 0"/>
      <geometry>
        <cylinder length="0.02" radius="0.05"/>
      </geometry>
    </collision>
    <visual>
      <origin rpy="0 1.57079632679 1.57079632679" xyz="0 0 0"/>
      <geometry>
        <cylinder length="0.02" radius="0.05"/>
      </geometry>
    </visual>
    <inertial>
      <origin rpy="0 1.57079632679 1.57079632679" xyz="0 0 0"/>
      <mass value="1"/>
      <inertia ixx="1.0" ixy="0.0" ixz="0.0" iyy="1.0" iyz="0.0" izz="1.0"/>
    </inertial>
  </link>
  <gazebo reference="wheel_right_5">
    <mu1>1.5</mu1>
    <mu2>1.5</mu2>
  </gazebo>
  <link name="caster_front_5">
    <visual>
      <origin rpy="0 0 0" xyz="0 0 0"/>
      <geometry>
        <sphere radius="0.05"/>
      </geometry>
    </visual>
    <inertial>
      <origin rpy="0 0 0" xyz="0 0 0"/>
      <mass value="1"/>
      <inertia ixx="1.0" ixy="0.0" ixz="0.0" iyy="1.0" iyz="0.0" izz="1.0"/>
    </inertial>
  </link>
  <link name="caster_back_5">
    <visual>
      <origin rpy="0 0 0" xyz="0 0 0"/>
      <geometry>
        <sphere radius="0.05"/>
      </geometry>
    </visual>
    <inertial>
      <origin rpy="0 0 0" xyz="0 0 0"/>
      <mass value="1"/>
      <inertia ixx="1.0" ixy="0.0" ixz="0.0" iyy="1.0" iyz="0.0" izz="1.0"/>
    </inertial>
  </link>
  <joint name="leftJoint_5" type="continuous">
    <parent link="car_5"/>
    <child link="wheel_left_5"/>
    <origin rpy="0 0 0" xyz="-0.175 0.062 0.05"/>
    <axis xyz="0 1 0"/>
  </joint>
  <joint name="rightJoint_5" type="continuous">
    <parent link="car_5"/>
    <child link="wheel_right_5"/>
    <origin rpy="0 0 0" xyz="-0.175 -0.062 0.05"/>
    <axis xyz="0 1 0"/>
  </joint>
  <joint name="frontJoint_5" type="fixed">
    <parent link="car_5"/>
    <child link="caster_front_5"/>
    <origin rpy="0 0 0" xyz="-0.05 0 0.08"/>
  </joint>
  <joint name="backJoint_5" type="fixed">
    <parent link="car_5"/>
    <child link="caster_back_5"/>
    <origin rpy="0 0 0" xyz="-0.3 0 0.08"/>
  </joint>
  <link name="car_6">
    <collision>
      <origin rpy="0 0 0" xyz="-0.175 0 0.08"/>
      <geometry>
        <box size="0.25 0.1 0.1"/>
      </geometry>
    </collision>
    <visual>
      <origin rpy="0 0 0" xyz="-0.175 0 0.08"/>
      <geometry>
        <box size="0.25 0.1 0.1"/>
      </geometry>
    </visual>
    <inertial>
      <origin rpy="0 0 0" xyz="-0.175 0 0.08"/>
      <mass value="1"/>
      <inertia ixx="1.0" ixy="0.0" ixz="0.0" iyy="1.0" iyz="0.0" izz="1.0"/>
    </inertial>
  </link>
  <link name="wheel_left_6">
    <collision>
      <origin rpy="0 1.57079632679 1.57079632679" xyz="0 0 0"/>
      <geometry>
        <cylinder length="0.02" radius="0.05"/>
      </geometry>
    </collision>
    <visual>
      <origin rpy="0 1.57079632679 1.57079632679" xyz="0 0 0"/>
      <geometry>
        <cylinder length="0.02" radius="0.05"/>
      </geometry>
    </visual>
    <inertial>
      <origin rpy="0 1.57079632679 1.57079632679" xyz="0 0 0"/>
      <mass value="1"/>
      <inertia ixx="1.0" ixy="0.0" ixz="0.0" iyy="1.0" iyz="0.0" izz="1.0"/>
    </inertial>
  </link>
  <gazebo reference="wheel_left_6">
    <mu1>1.5</mu1>
    <mu2>1.5</mu2>
  </gazebo>
  <link name="wheel_right_6">
    <collision>
      <origin rpy="0 1.57079632679 1.57079632679" xyz="0 0 0"/>
      <geometry>
        <cylinder length="0.02" radius="0.05"/>
      </geometry>
    </collision>
    <visual>
      <origin rpy="0 1.57079632679 1.57079632679" xyz="0 0 0"/>
      <geometry>
        <cylinder length="0.02" radius="0.05"/>
      </geometry>
    </visual>
    <inertial>
      <origin rpy="0 1.57079632679 1.57079632679" xyz="0 0 0"/>
      <mass value="1"/>
      <inertia ixx="1.0" ixy="0.0" ixz="0.0" iyy="1.0" iyz="0.0" izz="1.0"/>
    </inertial>
  </link>
  <gazebo reference="wheel_right_6">
    <mu1>1.5</mu1>
    <mu2>1.5</mu2>
  </gazebo>
  <link name="caster_front_6">
    <visual>
      <origin rpy="0 0 0" xyz="0 0 0"/>
      <geometry>
        <sphere radius="0.05"/>
      </geometry>
    </visual>
    <inertial>
      <origin rpy="0 0 0" xyz="0 0 0"/>
      <mass value="1"/>
      <inertia ixx="1.0" ixy="0.0" ixz="0.0" iyy="1.0" iyz="0.0" izz="1.0"/>
    </inertial>
  </link>
  <link name="caster_back_6">
    <visual>
      <origin rpy="0 0 0" xyz="0 0 0"/>
      <geometry>
        <sphere radius="0.05"/>
      </geometry>
    </visual>
    <inertial>
      <origin rpy="0 0 0" xyz="0 0 0"/>
      <mass value="1"/>
      <inertia ixx="1.0" ixy="0.0" ixz="0.0" iyy="1.0" iyz="0.0" izz="1.0"/>
    </inertial>
  </link>
  <joint name="leftJoint_6" type="continuous">
    <parent link="car_6"/>
    <child link="wheel_left_6"/>
    <origin rpy="0 0 0" xyz="-0.175 0.062 0.05"/>
    <axis xyz="0 1 0"/>
  </joint>
  <joint name="rightJoint_6" type="continuous">
    <parent link="car_6"/>
    <child link="wheel_right_6"/>
    <origin rpy="0 0 0" xyz="-0.175 -0.062 0.05"/>
    <axis xyz="0 1 0"/>
  </joint>
  <joint name="frontJoint_6" type="fixed">
    <parent link="car_6"/>
    <child link="caster_front_6"/>
    <origin rpy="0 0 0" xyz="-0.05 0 0.08"/>
  </joint>
  <joint name="backJoint_6" type="fixed">
    <parent link="car_6"/>
    <child link="caster_back_6"/>
    <origin rpy="0 0 0" xyz="-0.3 0 0.08"/>
  </joint>
  <link name="car_7">
    <collision>
      <origin rpy="0 0 0" xyz="-0.175 0 0.08"/>
      <geometry>
        <box size="0.25 0.1 0.1"/>
      </geometry>
    </collision>
    <visual>
      <origin rpy="0 0 0" xyz="-0.175 0 0.08"/>
      <geometry>
        <box size="0.25 0.1 0.1"/>
      </geometry>
    </visual>
    <inertial>
      <origin rpy="0 0 0" xyz="-0.175 0 0.08"/>
      <mass value="1"/>
      <inertia ixx="1.0" ixy="0.0" ixz="0.0" iyy="1.0" iyz="0.0" izz="1.0"/>
    </inertial>
  </link>
  <link name="wheel_left_7">
    <collision>
      <origin rpy="0 1.57079632679 1.57079632679" xyz="0 0 0"/>
      <geometry>
        <cylinder length="0.02" radius="0.05"/>
      </geometry>
    </collision>
    <visual>
      <origin rpy="0 1.57079632679 1.57079632679" xyz="0 0 0"/>
      <geometry>
        <cylinder length="0.02" radius="0.05"/>
      </geometry>
    </visual>
    <inertial>
      <origin rpy="0 1.57079632679 1.57079632679" xyz="0 0 0"/>
      <mass value="1"/>
      <inertia ixx="1.0" ixy="0.0" ixz="0.0" iyy="1.0" iyz="0.0" izz="1.0"/>
    </inertial>
  </link>
  <gazebo reference="wheel_left_7">
    <mu1>1.5</mu1>
    <mu2>1.5</mu2>
  </gazebo>
  <link name="wheel_right_7">
    <collision>
      <origin rpy="0 1.57079632679 1.57079632679" xyz="0 0 0"/>
      <geometry>
        <cylinder length="0.02" radius="0.05"/>
      </geometry>
    </collision>
    <visual>
      <origin rpy="0 1.57079632679 1.57079632679" xyz="0 0 0"/>
      <geometry>
        <cylinder length="0.02" radius="0.05"/>
      </geometry>
    </visual>
    <inertial>
      <origin rpy="0 1.57079632679 1.57079632679" xyz="0 0 0"/>
      <mass value="1"/>
      <inertia ixx="1.0" ixy="0.0" ixz="0.0" iyy="1.0" iyz="0.0" izz="1.0"/>
    </inertial>
  </link>
  <gazebo reference="wheel_right_7">
    <mu1>1.5</mu1>
    <mu2>1.5</mu2>
  </gazebo>
  <link name="caster_front_7">
    <visual>
      <origin rpy="0 0 0" xyz="0 0 0"/>
      <geometry>
        <sphere radius="0.05"/>
      </geometry>
    </visual>
    <inertial>
      <origin rpy="0 0 0" xyz="0 0 0"/>
      <mass value="1"/>
      <inertia ixx="1.0" ixy="0.0" ixz="0.0" iyy="1.0" iyz="0.0" izz="1.0"/>
    </inertial>
  </link>
  <link name="caster_back_7">
    <visual>
      <origin rpy="0 0 0" xyz="0 0 0"/>
      <geometry>
        <sphere radius="0.05"/>
      </geometry>
    </visual>
    <inertial>
      <origin rpy="0 0 0" xyz="0 0 0"/>
      <mass value="1"/>
      <inertia ixx="1.0" ixy="0.0" ixz="0.0" iyy="1.0" iyz="0.0" izz="1.0"/>
    </inertial>
  </link>
  <joint name="leftJoint_7" type="continuous">
    <parent link="car_7"/>
    <child link="wheel_left_7"/>
    <origin rpy="0 0 0" xyz="-0.175 0.062 0.05"/>
    <axis xyz="0 1 0"/>
  </joint>
  <joint name="rightJoint_7" type="continuous">
    <parent link="car_7"/>
    <child link="wheel_right_7"/>
    <origin rpy="0 0 0" xyz="-0.175 -0.062 0.05"/>
    <axis xyz="0 1 0"/>
  </joint>
  <joint name="frontJoint_7" type="fixed">
    <parent link="car_7"/>
    <child link="caster_front_7"/>
    <origin rpy="0 0 0" xyz="-0.05 0 0.08"/>
  </joint>
  <joint name="backJoint_7" type="fixed">
    <parent link="car_7"/>
    <child link="caster_back_7"/>
    <origin rpy="0 0 0" xyz="-0.3 0 0.08"/>
  </joint>
  <link name="car_8">
    <collision>
      <origin rpy="0 0 0" xyz="-0.175 0 0.08"/>
      <geometry>
        <box size="0.25 0.1 0.1"/>
      </geometry>
    </collision>
    <visual>
      <origin rpy="0 0 0" xyz="-0.175 0 0.08"/>
      <geometry>
        <box size="0.25 0.1 0.1"/>
      </geometry>
    </visual>
    <inertial>
      <origin rpy="0 0 0" xyz="-0.175 0 0.08"/>
      <mass value="1"/>
      <inertia ixx="1.0" ixy="0.0" ixz="0.0" iyy="1.0" iyz="0.0" izz="1.0"/>
    </inertial>
  </link>
  <link name="wheel_left_8">
    <collision>
      <origin rpy="0 1.57079632679 1.57079632679" xyz="0 0 0"/>
      <geometry>
        <cylinder length="0.02" radius="0.05"/>
      </geometry>
    </collision>
    <visual>
      <origin rpy="0 1.57079632679 1.57079632679" xyz="0 0 0"/>
      <geometry>
        <cylinder length="0.02" radius="0.05"/>
      </geometry>
    </visual>
    <inertial>
      <origin rpy="0 1.57079632679 1.57079632679" xyz="0 0 0"/>
      <mass value="1"/>
      <inertia ixx="1.0" ixy="0.0" ixz="0.0" iyy="1.0" iyz="0.0" izz="1.0"/>
    </inertial>
  </link>
  <gazebo reference="wheel_left_8">
    <mu1>1.5</mu1>
    <mu2>1.5</mu2>
  </gazebo>
  <link name="wheel_right_8">
    <collision>
      <origin rpy="0 1.57079632679 1.57079632679" xyz="0 0 0"/>
      <geometry>
        <cylinder length="0.02" radius="0.05"/>
      </geometry>
    </collision>
    <visual>
      <origin rpy="0 1.57079632679 1.57079632679" xyz="0 0 0"/>
      <geometry>
        <cylinder length="0.02" radius="0.05"/>
      </geometry>
    </visual>
    <inertial>
      <origin rpy="0 1.57079632679 1.57079632679" xyz="0 0 0"/>
      <mass value="1"/>
      <inertia ixx="1.0" ixy="0.0" ixz="0.0" iyy="1.0" iyz="0.0" izz="1.0"/>
    </inertial>
  </link>
  <gazebo reference="wheel_right_8">
    <mu1>1.5</mu1>
    <mu2>1.5</mu2>
  </gazebo>
  <link name="caster_front_8">
    <visual>
      <origin rpy="0 0 0" xyz="0 0 0"/>
      <geometry>
        <sphere radius="0.05"/>
      </geometry>
    </visual>
    <inertial>
      <origin rpy="0 0 0" xyz="0 0 0"/>
      <mass value="1"/>
      <inertia ixx="1.0" ixy="0.0" ixz="0.0" iyy="1.0" iyz="0.0" izz="1.0"/>
    </inertial>
  </link>
  <link name="caster_back_8">
    <visual>
      <origin rpy="0 0 0" xyz="0 0 0"/>
      <geometry>
        <sphere radius="0.05"/>
      </geometry>
    </visual>
    <inertial>
      <origin rpy="0 0 0" xyz="0 0 0"/>
      <mass value="1"/>
      <inertia ixx="1.0" ixy="0.0" ixz="0.0" iyy="1.0" iyz="0.0" izz="1.0"/>
    </inertial>
  </link>
  <joint name="leftJoint_8" type="continuous">
    <parent link="car_8"/>
    <child link="wheel_left_8"/>
    <origin rpy="0 0 0" xyz="-0.175 0.062 0.05"/>
    <axis xyz="0 1 0"/>
  </joint>
  <joint name="rightJoint_8" type="continuous">
    <parent link="car_8"/>
    <child link="wheel_right_8"/>
    <origin rpy="0 0 0" xyz="-0.175 -0.062 0.05"/>
    <axis xyz="0 1 0"/>
  </joint>
  <joint name="frontJoint_8" type="fixed">
    <parent link="car_8"/>
    <child link="caster_front_8"/>
    <origin rpy="0 0 0" xyz="-0.05 0 0.08"/>
  </joint>
  <joint name="backJoint_8" type="fixed">
    <parent link="car_8"/>
    <child link="caster_back_8"/>
    <origin rpy="0 0 0" xyz="-0.3 0 0.08"/>
  </joint>
  <link name="car_9">
    <collision>
      <origin rpy="0 0 0" xyz="-0.175 0 0.08"/>
      <geometry>
        <box size="0.25 0.1 0.1"/>
      </geometry>
    </collision>
    <visual>
      <origin rpy="0 0 0" xyz="-0.175 0 0.08"/>
      <geometry>
        <box size="0.25 0.1 0.1"/>
      </geometry>
    </visual>
    <inertial>
      <origin rpy="0 0 0" xyz="-0.175 0 0.08"/>
      <mass value="1"/>
      <inertia ixx="1.0" ixy="0.0" ixz="0.0" iyy="1.0" iyz="0.0" izz="1.0"/>
    </inertial>
  </link>
  <link name="wheel_left_9">
    <collision>
      <origin rpy="0 1.57079632679 1.57079632679" xyz="0 0 0"/>
      <geometry>
        <cylinder length="0.02" radius="0.05"/>
      </geometry>
    </collision>
    <visual>
      <origin rpy="0 1.57079632679 1.57079632679" xyz="0 0 0"/>
      <geometry>
        <cylinder length="0.02" radius="0.05"/>
      </geometry>
    </visual>
    <inertial>
      <origin rpy="0 1.57079632679 1.57079632679" xyz="0 0 0"/>
      <mass value="1"/>
      <inertia ixx="1.0" ixy="0.0" ixz="0.0" iyy="1.0" iyz="0.0" izz="1.0"/>
    </inertial>
  </link>
  <gazebo reference="wheel_left_9">
    <mu1>1.5</mu1>
    <mu2>1.5</mu2>
  </gazebo>
  <link name="wheel_right_9">
    <collision>
      <origin rpy="0 1.57079632679 1.57079632679" xyz="0 0 0"/>
      <geometry>
        <cylinder length="0.02" radius="0.05"/>
      </geometry>
    </collision>
    <visual>
      <origin rpy="0 1.57079632679 1.57079632679" xyz="0 0 0"/>
      <geometry>
        <cylinder length="0.02" radius="0.05"/>
      </geometry>
    </visual>
    <inertial>
      <origin rpy="0 1.57079632679 1.57079632679" xyz="0 0 0"/>
      <mass value="1"/>
      <inertia ixx="1.0" ixy="0.0" ixz="0.0" iyy="1.0" iyz="0.0" izz="1.0"/>
    </inertial>
  </link>
  <gazebo reference="wheel_right_9">
    <mu1>1.5</mu1>
    <mu2>1.5</mu2>
  </gazebo>
  <link name="caster_front_9">
    <visual>
      <origin rpy="0 0 0" xyz="0 0 0"/>
      <geometry>
        <sphere radius="0.05"/>
      </geometry>
    </visual>
    <inertial>
      <origin rpy="0 0 0" xyz="0 0 0"/>
      <mass value="1"/>
      <inertia ixx="1.0" ixy="0.0" ixz="0.0" iyy="1.0" iyz="0.0" izz="1.0"/>
    </inertial>
  </link>
  <link name="caster_back_9">
    <visual>
      <origin rpy="0 0 0" xyz="0 0 0"/>
      <geometry>
        <sphere radius="0.05"/>
      </geometry>
    </visual>
    <inertial>
      <origin rpy="0 0 0" xyz="0 0 0"/>
      <mass value="1"/>
      <inertia ixx="1.0" ixy="0.0" ixz="0.0" iyy="1.0" iyz="0.0" izz="1.0"/>
    </inertial>
  </link>
  <joint name="leftJoint_9" type="continuous">
    <parent link="car_9"/>
    <child link="wheel_left_9"/>
    <origin rpy="0 0 0" xyz="-0.175 0.062 0.05"/>
    <axis xyz="0 1 0"/>
  </joint>
  <joint name="rightJoint_9" type="continuous">
    <parent link="car_9"/>
    <child link="wheel_right_9"/>
    <origin rpy="0 0 0" xyz="-0.175 -0.062 0.05"/>
    <axis xyz="0 1 0"/>
  </joint>
  <joint name="frontJoint_9" type="fixed">
    <parent link="car_9"/>
    <child link="caster_front_9"/>
    <origin rpy="0 0 0" xyz="-0.05 0 0.08"/>
  </joint>
  <joint name="backJoint_9" type="fixed">
    <parent link="car_9"/>
    <child link="caster_back_9"/>
    <origin rpy="0 0 0" xyz="-0.3 0 0.08"/>
  </joint>
  <joint name="joint_1" type="revolute">
    <parent link="car_1"/>
    <child link="car_2"/>
    <origin rpy="0 0 0" xyz="-0.35 0 0"/>
    <limit effort="1000.0" lower="-1.57079632679" upper="1.57079632679" velocity="50"/>
    <axis xyz="0 0 1"/>
  </joint>
  <transmission name="trans_1">
    <type>transmission_interface/SimpleTransmission</type>
    <joint name="joint_1">
      <hardwareInterface>hardware_interface/EffortJointInterface</hardwareInterface>
    </joint>
    <actuator name="motor_1">
      <hardwareInterface>hardware_interface/EffortJointInterface</hardwareInterface>
      <mechanicalReduction>1</mechanicalReduction>
    </actuator>
  </transmission>
  <joint name="joint_2" type="revolute">
    <parent link="car_2"/>
    <child link="car_3"/>
    <origin rpy="0 0 0" xyz="-0.35 0 0"/>
    <limit effort="1000.0" lower="-1.57079632679" upper="1.57079632679" velocity="50"/>
    <axis xyz="0 0 1"/>
  </joint>
  <transmission name="trans_2">
    <type>transmission_interface/SimpleTransmission</type>
    <joint name="joint_2">
      <hardwareInterface>hardware_interface/EffortJointInterface</hardwareInterface>
    </joint>
    <actuator name="motor_2">
      <hardwareInterface>hardware_interface/EffortJointInterface</hardwareInterface>
      <mechanicalReduction>1</mechanicalReduction>
    </actuator>
  </transmission>
  <joint name="joint_3" type="revolute">
    <parent link="car_3"/>
    <child link="car_4"/>
    <origin rpy="0 0 0" xyz="-0.35 0 0"/>
    <limit effort="1000.0" lower="-1.57079632679" upper="1.57079632679" velocity="50"/>
    <axis xyz="0 0 1"/>
  </joint>
  <transmission name="trans_3">
    <type>transmission_interface/SimpleTransmission</type>
    <joint name="joint_3">
      <hardwareInterface>hardware_interface/EffortJointInterface</hardwareInterface>
    </joint>
    <actuator name="motor_3">
      <hardwareInterface>hardware_interface/EffortJointInterface</hardwareInterface>
      <mechanicalReduction>1</mechanicalReduction>
    </actuator>
  </transmission>
  <joint name="joint_4" type="revolute">
    <parent link="car_4"/>
    <child link="car_5"/>
    <origin rpy="0 0 0" xyz="-0.35 0 0"/>
    <limit effort="1000.0" lower="-1.57079632679" upper="1.57079632679" velocity="50"/>
    <axis xyz="0 0 1"/>
  </joint>
  <transmission name="trans_4">
    <type>transmission_interface/SimpleTransmission</type>
    <joint name="joint_4">
      <hardwareInterface>hardware_interface/EffortJointInterface</hardwareInterface>
    </joint>
    <actuator name="motor_4">
      <hardwareInterface>hardware_interface/EffortJointInterface</hardwareInterface>
      <mechanicalReduction>1</mechanicalReduction>
    </actuator>
  </transmission>
  <joint name="joint_5" type="revolute">
    <parent link="car_5"/>
    <child link="car_6"/>
    <origin rpy="0 0 0" xyz="-0.35 0 0"/>
    <limit effort="1000.0" lower="-1.57079632679" upper="1.57079632679" velocity="50"/>
    <axis xyz="0 0 1"/>
  </joint>
  <transmission name="trans_5">
    <type>transmission_interface/SimpleTransmission</type>
    <joint name="joint_5">
      <hardwareInterface>hardware_interface/EffortJointInterface</hardwareInterface>
    </joint>
    <actuator name="motor_5">
      <hardwareInterface>hardware_interface/EffortJointInterface</hardwareInterface>
      <mechanicalReduction>1</mechanicalReduction>
    </actuator>
  </transmission>
  <joint name="joint_6" type="revolute">
    <parent link="car_6"/>
    <child link="car_7"/>
    <origin rpy="0 0 0" xyz="-0.35 0 0"/>
    <limit effort="1000.0" lower="-1.57079632679" upper="1.57079632679" velocity="50"/>
    <axis xyz="0 0 1"/>
  </joint>
  <transmission name="trans_6">
    <type>transmission_interface/SimpleTransmission</type>
    <joint name="joint_6">
      <hardwareInterface>hardware_interface/EffortJointInterface</hardwareInterface>
    </joint>
    <actuator name="motor_6">
      <hardwareInterface>hardware_interface/EffortJointInterface</hardwareInterface>
      <mechanicalReduction>1</mechanicalReduction>
    </actuator>
  </transmission>
  <joint name="joint_7" type="revolute">
    <parent link="car_7"/>
    <child link="car_8"/>
    <origin rpy="0 0 0" xyz="-0.35 0 0"/>
    <limit effort="1000.0" lower="-1.57079632679" upper="1.57079632679" velocity="50"/>
    <axis xyz="0 0 1"/>
  </joint>
  <transmission name="trans_7">
    <type>transmission_interface/SimpleTransmission</type>
    <joint name="joint_7">
      <hardwareInterface>hardware_interface/EffortJointInterface</hardwareInterface>
    </joint>
    <actuator name="motor_7">
      <hardwareInterface>hardware_interface/EffortJointInterface</hardwareInterface>
      <mechanicalReduction>1</mechanicalReduction>
    </actuator>
  </transmission>
  <joint name="joint_8" type="revolute">
    <parent link="car_8"/>
    <child link="car_9"/>
    <origin rpy="0 0 0" xyz="-0.35 0 0"/>
    <limit effort="1000.0" lower="-1.57079632679" upper="1.57079632679" velocity="50"/>
    <axis xyz="0 0 1"/>
  </joint>
  <transmission name="trans_8">
    <type>transmission_interface/SimpleTransmission</type>
    <joint name="joint_8">
      <hardwareInterface>hardware_interface/EffortJointInterface</hardwareInterface>
    </joint>
    <actuator name="motor_8">
      <hardwareInterface>hardware_interface/EffortJointInterface</hardwareInterface>
      <mechanicalReduction>1</mechanicalReduction>
    </actuator>
  </transmission>
</robot>

